INFO:faiss.loader:Loading faiss with AVX2 support.
INFO:faiss.loader:Successfully loaded faiss with AVX2 support.
INFO:faiss.loader:Loading faiss with AVX2 support.
INFO:faiss.loader:Successfully loaded faiss with AVX2 support.
INFO:root:called-params configs/inat18.yaml
INFO:root:loaded params...
[W socket.cpp:464] [c10d] The server socket has failed to bind to [::]:40151 (errno: 98 - Address already in use).
[W socket.cpp:464] [c10d] The server socket has failed to bind to 0.0.0.0:40151 (errno: 98 - Address already in use).
[E socket.cpp:500] [c10d] The server socket has failed to listen on any local network address.
{   'data': {   'K_range': [2, 3, 4, 5],
                'batch_size': 96,
                'cache_path': '/home/rtcalumby/adam/luciano/DeepCluster/cache/inat18',
                'color_jitter_strength': 0.0,
                'crop_scale': [0.3, 1.0],
                'crop_size': 224,
                'cutmix': 0.0,
                'drop_path': 0.25,
                'image_folder': '/home/rtcalumby/adam/luciano/inat18/',
                'mixup': 0.0,
                'nb_classes': 8142,
                'num_workers': 16,
                'pin_mem': True,
                'reprob': 0.25,
                'resume_epoch': 0,
                'root_path': '/home/rtcalumby/adam/luciano/',
                'use_color_distortion': False,
                'use_gaussian_blur': False,
                'use_horizontal_flip': False},
    'logging': {   'folder': '/home/rtcalumby/adam/luciano/inat18/logs/exp_1',
                   'write_tag': 'jepa'},
    'mask': {   'allow_overlap': False,
                'aspect_ratio': [0.75, 1.5],
                'enc_mask_scale': [0.85, 1.0],
                'min_keep': 10,
                'num_enc_masks': 1,
                'num_pred_masks': 4,
                'patch_size': 14,
                'pred_mask_scale': [0.15, 0.2]},
    'meta': {   'copy_data': False,
                'load_checkpoint': True,
                'model_name': 'vit_huge',
                'pred_depth': 12,
                'pred_emb_dim': 384,
                'read_checkpoint': None,
                'use_bfloat16': True},
    'optimization': {   'ema': [0.9, 0.999],
                        'epochs': 50,
                        'final_lr': 5e-05,
                        'final_weight_decay': 0.4,
                        'ipe_scale': 1.0,
                        'label_smoothing': 0.1,
                        'lr': 0.001,
                        'start_lr': 0.0001,
                        'warmup': 25,
                        'weight_decay': 0.05}}
INFO:root:distributed training not available The server socket has failed to listen on any local network address. The server socket has failed to bind to [::]:40151 (errno: 98 - Address already in use). The server socket has failed to bind to 0.0.0.0:40151 (errno: 98 - Address already in use).
INFO:root:Running... (rank: 0/1)
INFO:root:SLURM vars not set (distributed training not available)
INFO:root:Initialized (rank/world-size) 0/1
Process Process-1:
Traceback (most recent call last):
  File "/home/rtcalumby/miniconda3/envs/py382/lib/python3.12/multiprocessing/process.py", line 314, in _bootstrap
    self.run()
  File "/home/rtcalumby/miniconda3/envs/py382/lib/python3.12/multiprocessing/process.py", line 108, in run
    self._target(*self._args, **self._kwargs)
  File "/home/rtcalumby/adam/luciano/LifeCLEFPlant2022/DeepCluster/main_FGDCC_v2.py", line 52, in process_main
    app_main(args=params)
  File "/home/rtcalumby/adam/luciano/LifeCLEFPlant2022/DeepCluster/engine_FGDCCv2.py", line 243, in main
    target_encoder = DistributedDataParallel(target_encoder, static_graph=True)
                     ^^^^^^^^^^^^^^^^^^^^^^^^^^^^^^^^^^^^^^^^^^^^^^^^^^^^^^^^^^
  File "/home/rtcalumby/miniconda3/envs/py382/lib/python3.12/site-packages/torch/nn/parallel/distributed.py", line 731, in __init__
    self.process_group = _get_default_group()
                         ^^^^^^^^^^^^^^^^^^^^
  File "/home/rtcalumby/miniconda3/envs/py382/lib/python3.12/site-packages/torch/distributed/distributed_c10d.py", line 1008, in _get_default_group
    raise ValueError(
ValueError: Default process group has not been initialized, please make sure to call init_process_group.
